## 提前终止生成器

一个实现 Iterator 接口的对象一定有 next 方法，还有可选的方法 return 、 throw。

return 、throw 都可以强制使生成器进入关闭状态。



## return() - 强制生成器进入关闭状态

+ **retrun 方法接受的值，就是终止迭代器对象的值。**

+ **与迭代器不同的是，所有的生成器中都有 return方法。**
+ **进入关闭状态的生成器，是不可逆的，不可恢复的。**

```js
function* generatorFn() {
    yield 1;
    yield 2;
    yield 3;
}

const g = generatorFn();

// 生成器对象 g
console.log(g); // generatorFn {<suspended>}
console.log(g.next()); // { value: 1, done: false }

// return 强制关闭生成器
console.log(g.return(0)); //{ value: 0, done: true }

// 关闭后的生成器无法恢复，后续结果都是 { value: undefined, done: true }
console.log(g.next()); // { value: undefined, done: true }
```



**for-of 循环等内置语言结构会忽略状态为 done: true 的 IteratorObject 内部返回的值。**

```js
function* generatorFn() {
    yield 1;
    yield 2;
    yield 3;
}

const g = generatorFn();

for (const x of g) {
    if (x > 1) {
        g.return(0);
    }
    console.log(x);
}
// 1 2
```



## throw - 暂停时、注入错误、不处理、关闭生成器

throw() 方法会在暂停的时候将一个提供的错误注入到生成器对象中。如果错误未被处理，生成器就会关闭。

```js
function* generatorFn() {
    yield 1;
    yield 2;
    yield 3;
}

const g = generatorFn();

try {
  	// 注入一个错误
    g.throw(1);
} catch(e) {
    console.log(e); // 1
}

// 在生成器中未对错误进行处理
// 生成器状态进入关闭
console.log(g); // generatorFn {<close>}

// 进入关闭状态无法恢复
console.log(g.next());  // { value: undefined, done: true }
```



**生成器内部处理了错误，那么生成器就不会关闭。错误处理会跳过当前对应 yield 的值，通过这个 yield 抛出错误**

```js
function* generatorFn() {
    for (const x of [1, 2, 3]) {
    		// 每个 yeild 都会做异常处理  
        try {
            yield x;
        } catch (e) {}
    }
}

const g = generatorFn();

console.log(g.next()); // { value: 1, done: false }
g.throw('error'); 
console.log(g.next()); // { value: 3, done: false }
```

